[2023-06-19 18:00:09,810] INFO in _internal: [31m[1mWARNING: This is a development server. Do not use it in a production deployment. Use a production WSGI server instead.[0m
 * Running on http://127.0.0.1:5000
[2023-06-19 18:00:09,810] INFO in _internal: [33mPress CTRL+C to quit[0m
[2023-06-19 18:00:25,066] INFO in _internal: 127.0.0.1 - - [19/Jun/2023 18:00:25] "GET / HTTP/1.1" 200 -
[2023-06-19 18:00:28,303] INFO in _internal: 127.0.0.1 - - [19/Jun/2023 18:00:28] "[33mGET /favicon.ico HTTP/1.1[0m" 404 -
[2023-06-19 18:00:28,790] INFO in _internal: 127.0.0.1 - - [19/Jun/2023 18:00:28] "GET /login HTTP/1.1" 200 -
[2023-06-19 18:01:06,661] ERROR in routes: Invalid credentials entered for user: aman
[2023-06-19 18:01:06,663] INFO in _internal: 127.0.0.1 - - [19/Jun/2023 18:01:06] "[32mPOST /login HTTP/1.1[0m" 302 -
[2023-06-19 18:01:06,678] INFO in _internal: 127.0.0.1 - - [19/Jun/2023 18:01:06] "GET /login HTTP/1.1" 200 -
[2023-06-19 18:01:13,037] INFO in _internal: 127.0.0.1 - - [19/Jun/2023 18:01:13] "GET /register HTTP/1.1" 200 -
[2023-06-19 18:08:47,469] INFO in _internal: 127.0.0.1 - - [19/Jun/2023 18:08:47] "[32mPOST /register HTTP/1.1[0m" 302 -
[2023-06-19 18:08:47,481] INFO in _internal: 127.0.0.1 - - [19/Jun/2023 18:08:47] "GET /register HTTP/1.1" 200 -
[2023-06-19 18:09:57,962] INFO in _internal: 127.0.0.1 - - [19/Jun/2023 18:09:57] "[32mPOST /register HTTP/1.1[0m" 302 -
[2023-06-19 18:09:57,970] INFO in _internal: 127.0.0.1 - - [19/Jun/2023 18:09:57] "GET /register HTTP/1.1" 200 -
[2023-06-19 18:10:00,161] INFO in routes: User registered: Selam10
[2023-06-19 18:10:00,162] INFO in _internal: 127.0.0.1 - - [19/Jun/2023 18:10:00] "[32mPOST /register HTTP/1.1[0m" 302 -
[2023-06-19 18:10:35,928] ERROR in routes: Username already taken: Selam10
[2023-06-19 18:10:35,930] INFO in _internal: 127.0.0.1 - - [19/Jun/2023 18:10:35] "[32mPOST /register HTTP/1.1[0m" 302 -
[2023-06-19 18:10:35,938] INFO in _internal: 127.0.0.1 - - [19/Jun/2023 18:10:35] "GET /register HTTP/1.1" 200 -
[2023-06-19 18:17:04,389] INFO in routes: Email verified for user: Selam10
[2023-06-19 18:17:04,391] INFO in _internal: 127.0.0.1 - - [19/Jun/2023 18:17:04] "[32mGET /verify/IlNlbGFtMTAi.ZJBvvQ.mXE_ooVpde9JYnhVHRpHab6Joa8 HTTP/1.1[0m" 302 -
[2023-06-19 18:17:04,399] INFO in _internal: 127.0.0.1 - - [19/Jun/2023 18:17:04] "GET /login HTTP/1.1" 200 -
[2023-06-19 18:18:38,713] INFO in routes: User logged in: Selam10
[2023-06-19 18:18:38,714] INFO in _internal: 127.0.0.1 - - [19/Jun/2023 18:18:38] "[32mPOST /login HTTP/1.1[0m" 302 -
[2023-06-19 18:18:38,745] INFO in _internal: 127.0.0.1 - - [19/Jun/2023 18:18:38] "GET /dashboard HTTP/1.1" 200 -
[2023-06-19 18:23:43,024] INFO in routes: New feedback submitted by user: Selam10
[2023-06-19 18:23:43,025] INFO in _internal: 127.0.0.1 - - [19/Jun/2023 18:23:43] "[32mPOST /feedback HTTP/1.1[0m" 302 -
[2023-06-19 18:23:43,039] INFO in _internal: 127.0.0.1 - - [19/Jun/2023 18:23:43] "GET /dashboard HTTP/1.1" 200 -
[2023-06-19 18:23:48,274] INFO in _internal: 127.0.0.1 - - [19/Jun/2023 18:23:48] "GET /uploads/4539ac070ed94d0198ec65cb9996b3fa.pdf HTTP/1.1" 200 -
[2023-06-19 18:23:54,349] INFO in _internal: 127.0.0.1 - - [19/Jun/2023 18:23:54] "[36mGET /uploads/4539ac070ed94d0198ec65cb9996b3fa.pdf HTTP/1.1[0m" 304 -
[2023-06-19 18:30:34,992] INFO in _internal: [31m[1mWARNING: This is a development server. Do not use it in a production deployment. Use a production WSGI server instead.[0m
 * Running on http://127.0.0.1:5000
[2023-06-19 18:30:34,992] INFO in _internal: [33mPress CTRL+C to quit[0m
[2023-06-19 18:30:54,454] INFO in _internal: 127.0.0.1 - - [19/Jun/2023 18:30:54] "GET /dashboard HTTP/1.1" 200 -
[2023-06-19 18:31:08,190] INFO in _internal: 127.0.0.1 - - [19/Jun/2023 18:31:08] "[33mGET /uploads/12a12856c1b143bf9b4a5c9e90b20260.pdf HTTP/1.1[0m" 404 -
[2023-06-19 18:31:08,433] INFO in _internal: 127.0.0.1 - - [19/Jun/2023 18:31:08] "GET /static/images/404.jpg HTTP/1.1" 200 -
[2023-06-19 18:31:19,251] ERROR in routes: Error deleting feedback
Traceback (most recent call last):
  File "C:\Users\sesel\OneDrive\Desktop\Projects\secure-web-app\app\routes.py", line 402, in delete_feedback
    os.remove(os.path.join(app.config['UPLOAD_FOLDER'], feedback.file))
FileNotFoundError: [WinError 2] The system cannot find the file specified: 'C:\\Users\\sesel\\OneDrive\\Desktop\\Projects\\secure-web-app\\uploads\\12a12856c1b143bf9b4a5c9e90b20260.pdf'
[2023-06-19 18:31:19,254] INFO in _internal: 127.0.0.1 - - [19/Jun/2023 18:31:19] "[32mPOST /feedback/delete/4 HTTP/1.1[0m" 302 -
[2023-06-19 18:31:19,269] INFO in _internal: 127.0.0.1 - - [19/Jun/2023 18:31:19] "GET /dashboard HTTP/1.1" 200 -
[2023-06-19 18:31:31,376] ERROR in routes: Error deleting feedback
Traceback (most recent call last):
  File "C:\Users\sesel\OneDrive\Desktop\Projects\secure-web-app\app\routes.py", line 402, in delete_feedback
    os.remove(os.path.join(app.config['UPLOAD_FOLDER'], feedback.file))
FileNotFoundError: [WinError 2] The system cannot find the file specified: 'C:\\Users\\sesel\\OneDrive\\Desktop\\Projects\\secure-web-app\\uploads\\12a12856c1b143bf9b4a5c9e90b20260.pdf'
[2023-06-19 18:31:31,379] INFO in _internal: 127.0.0.1 - - [19/Jun/2023 18:31:31] "[32mPOST /feedback/delete/4 HTTP/1.1[0m" 302 -
[2023-06-19 18:31:31,684] INFO in _internal: 127.0.0.1 - - [19/Jun/2023 18:31:31] "GET /dashboard HTTP/1.1" 200 -
[2023-06-19 18:33:15,484] INFO in _internal: 127.0.0.1 - - [19/Jun/2023 18:33:15] "[32mPOST /feedback HTTP/1.1[0m" 302 -
[2023-06-19 18:33:15,501] INFO in _internal: 127.0.0.1 - - [19/Jun/2023 18:33:15] "GET /dashboard HTTP/1.1" 200 -
[2023-06-19 18:33:51,689] INFO in routes: New feedback submitted by user: real
[2023-06-19 18:33:51,690] INFO in _internal: 127.0.0.1 - - [19/Jun/2023 18:33:51] "[32mPOST /feedback HTTP/1.1[0m" 302 -
[2023-06-19 18:33:51,988] INFO in _internal: 127.0.0.1 - - [19/Jun/2023 18:33:51] "GET /dashboard HTTP/1.1" 200 -
[2023-06-19 18:50:26,561] INFO in _internal: [31m[1mWARNING: This is a development server. Do not use it in a production deployment. Use a production WSGI server instead.[0m
 * Running on http://127.0.0.1:5000
[2023-06-19 18:50:26,561] INFO in _internal: [33mPress CTRL+C to quit[0m
[2023-06-19 18:50:35,116] INFO in _internal: 127.0.0.1 - - [19/Jun/2023 18:50:35] "GET /dashboard HTTP/1.1" 200 -
[2023-06-19 18:50:37,111] INFO in routes: User logged out: real
[2023-06-19 18:50:37,113] INFO in _internal: 127.0.0.1 - - [19/Jun/2023 18:50:37] "[32mGET /logout HTTP/1.1[0m" 302 -
[2023-06-19 18:50:37,131] INFO in _internal: 127.0.0.1 - - [19/Jun/2023 18:50:37] "GET / HTTP/1.1" 200 -
[2023-06-19 18:50:41,269] INFO in _internal: 127.0.0.1 - - [19/Jun/2023 18:50:41] "GET /register HTTP/1.1" 200 -
[2023-06-19 18:51:17,648] ERROR in app: Exception on /register [POST]
Traceback (most recent call last):
  File "C:\Users\sesel\OneDrive\Desktop\Projects\secure-web-app\venv\Lib\site-packages\sqlalchemy\engine\base.py", line 1968, in _exec_single_context
    self.dialect.do_execute(
  File "C:\Users\sesel\OneDrive\Desktop\Projects\secure-web-app\venv\Lib\site-packages\sqlalchemy\engine\default.py", line 920, in do_execute
    cursor.execute(statement, parameters)
sqlite3.OperationalError: database is locked

The above exception was the direct cause of the following exception:

Traceback (most recent call last):
  File "C:\Users\sesel\OneDrive\Desktop\Projects\secure-web-app\venv\Lib\site-packages\flask\app.py", line 2190, in wsgi_app
    response = self.full_dispatch_request()
               ^^^^^^^^^^^^^^^^^^^^^^^^^^^^
  File "C:\Users\sesel\OneDrive\Desktop\Projects\secure-web-app\venv\Lib\site-packages\flask\app.py", line 1486, in full_dispatch_request
    rv = self.handle_user_exception(e)
         ^^^^^^^^^^^^^^^^^^^^^^^^^^^^^
  File "C:\Users\sesel\OneDrive\Desktop\Projects\secure-web-app\venv\Lib\site-packages\flask\app.py", line 1484, in full_dispatch_request
    rv = self.dispatch_request()
         ^^^^^^^^^^^^^^^^^^^^^^^
  File "C:\Users\sesel\OneDrive\Desktop\Projects\secure-web-app\venv\Lib\site-packages\flask\app.py", line 1469, in dispatch_request
    return self.ensure_sync(self.view_functions[rule.endpoint])(**view_args)
           ^^^^^^^^^^^^^^^^^^^^^^^^^^^^^^^^^^^^^^^^^^^^^^^^^^^^^^^^^^^^^^^^^
  File "C:\Users\sesel\OneDrive\Desktop\Projects\secure-web-app\app\routes.py", line 114, in register
    user.save()
  File "C:\Users\sesel\OneDrive\Desktop\Projects\secure-web-app\app\models.py", line 36, in save
    db.session.commit()
  File "C:\Users\sesel\OneDrive\Desktop\Projects\secure-web-app\venv\Lib\site-packages\sqlalchemy\orm\scoping.py", line 553, in commit
    return self._proxied.commit()
           ^^^^^^^^^^^^^^^^^^^^^^
  File "C:\Users\sesel\OneDrive\Desktop\Projects\secure-web-app\venv\Lib\site-packages\sqlalchemy\orm\session.py", line 1906, in commit
    trans.commit(_to_root=True)
  File "<string>", line 2, in commit
  File "C:\Users\sesel\OneDrive\Desktop\Projects\secure-web-app\venv\Lib\site-packages\sqlalchemy\orm\state_changes.py", line 137, in _go
    ret_value = fn(self, *arg, **kw)
                ^^^^^^^^^^^^^^^^^^^^
  File "C:\Users\sesel\OneDrive\Desktop\Projects\secure-web-app\venv\Lib\site-packages\sqlalchemy\orm\session.py", line 1221, in commit
    self._prepare_impl()
  File "<string>", line 2, in _prepare_impl
  File "C:\Users\sesel\OneDrive\Desktop\Projects\secure-web-app\venv\Lib\site-packages\sqlalchemy\orm\state_changes.py", line 137, in _go
    ret_value = fn(self, *arg, **kw)
                ^^^^^^^^^^^^^^^^^^^^
  File "C:\Users\sesel\OneDrive\Desktop\Projects\secure-web-app\venv\Lib\site-packages\sqlalchemy\orm\session.py", line 1196, in _prepare_impl
    self.session.flush()
  File "C:\Users\sesel\OneDrive\Desktop\Projects\secure-web-app\venv\Lib\site-packages\sqlalchemy\orm\session.py", line 4154, in flush
    self._flush(objects)
  File "C:\Users\sesel\OneDrive\Desktop\Projects\secure-web-app\venv\Lib\site-packages\sqlalchemy\orm\session.py", line 4290, in _flush
    with util.safe_reraise():
  File "C:\Users\sesel\OneDrive\Desktop\Projects\secure-web-app\venv\Lib\site-packages\sqlalchemy\util\langhelpers.py", line 147, in __exit__
    raise exc_value.with_traceback(exc_tb)
  File "C:\Users\sesel\OneDrive\Desktop\Projects\secure-web-app\venv\Lib\site-packages\sqlalchemy\orm\session.py", line 4251, in _flush
    flush_context.execute()
  File "C:\Users\sesel\OneDrive\Desktop\Projects\secure-web-app\venv\Lib\site-packages\sqlalchemy\orm\unitofwork.py", line 467, in execute
    rec.execute(self)
  File "C:\Users\sesel\OneDrive\Desktop\Projects\secure-web-app\venv\Lib\site-packages\sqlalchemy\orm\unitofwork.py", line 644, in execute
    util.preloaded.orm_persistence.save_obj(
  File "C:\Users\sesel\OneDrive\Desktop\Projects\secure-web-app\venv\Lib\site-packages\sqlalchemy\orm\persistence.py", line 93, in save_obj
    _emit_insert_statements(
  File "C:\Users\sesel\OneDrive\Desktop\Projects\secure-web-app\venv\Lib\site-packages\sqlalchemy\orm\persistence.py", line 1223, in _emit_insert_statements
    result = connection.execute(
             ^^^^^^^^^^^^^^^^^^^
  File "C:\Users\sesel\OneDrive\Desktop\Projects\secure-web-app\venv\Lib\site-packages\sqlalchemy\engine\base.py", line 1413, in execute
    return meth(
           ^^^^^
  File "C:\Users\sesel\OneDrive\Desktop\Projects\secure-web-app\venv\Lib\site-packages\sqlalchemy\sql\elements.py", line 483, in _execute_on_connection
    return connection._execute_clauseelement(
           ^^^^^^^^^^^^^^^^^^^^^^^^^^^^^^^^^^
  File "C:\Users\sesel\OneDrive\Desktop\Projects\secure-web-app\venv\Lib\site-packages\sqlalchemy\engine\base.py", line 1637, in _execute_clauseelement
    ret = self._execute_context(
          ^^^^^^^^^^^^^^^^^^^^^^
  File "C:\Users\sesel\OneDrive\Desktop\Projects\secure-web-app\venv\Lib\site-packages\sqlalchemy\engine\base.py", line 1846, in _execute_context
    return self._exec_single_context(
           ^^^^^^^^^^^^^^^^^^^^^^^^^^
  File "C:\Users\sesel\OneDrive\Desktop\Projects\secure-web-app\venv\Lib\site-packages\sqlalchemy\engine\base.py", line 1987, in _exec_single_context
    self._handle_dbapi_exception(
  File "C:\Users\sesel\OneDrive\Desktop\Projects\secure-web-app\venv\Lib\site-packages\sqlalchemy\engine\base.py", line 2344, in _handle_dbapi_exception
    raise sqlalchemy_exception.with_traceback(exc_info[2]) from e
  File "C:\Users\sesel\OneDrive\Desktop\Projects\secure-web-app\venv\Lib\site-packages\sqlalchemy\engine\base.py", line 1968, in _exec_single_context
    self.dialect.do_execute(
  File "C:\Users\sesel\OneDrive\Desktop\Projects\secure-web-app\venv\Lib\site-packages\sqlalchemy\engine\default.py", line 920, in do_execute
    cursor.execute(statement, parameters)
sqlalchemy.exc.OperationalError: (sqlite3.OperationalError) database is locked
[SQL: INSERT INTO user (username, name, email, password, is_verified, is_blocked, registered_at, is_admin) VALUES (?, ?, ?, ?, ?, ?, ?, ?)]
[parameters: ('Selam10', 'Selamawit Elias', 'selamawitelias803@gmail.com', 'pbkdf2:sha256:600000$YaWM5AjeM9BO3Msa$d7293ee5c223d3346295e0690c4a737b5215ec96074b26764a0e51a3dd8468e2', 0, 0, '2023-06-19 15:51:12.158282', 0)]
(Background on this error at: https://sqlalche.me/e/20/e3q8)
[2023-06-19 18:51:17,684] INFO in _internal: 127.0.0.1 - - [19/Jun/2023 18:51:17] "[35m[1mPOST /register HTTP/1.1[0m" 500 -
[2023-06-19 18:51:17,844] INFO in _internal: 127.0.0.1 - - [19/Jun/2023 18:51:17] "GET /static/images/500.jpg HTTP/1.1" 200 -
[2023-06-19 18:52:37,350] INFO in routes: User registered: Selam10
[2023-06-19 18:52:37,351] INFO in _internal: 127.0.0.1 - - [19/Jun/2023 18:52:37] "[32mPOST /register HTTP/1.1[0m" 302 -
[2023-06-19 18:52:37,368] INFO in _internal: 127.0.0.1 - - [19/Jun/2023 18:52:37] "GET /login HTTP/1.1" 200 -
[2023-06-19 18:54:36,965] INFO in _internal: [31m[1mWARNING: This is a development server. Do not use it in a production deployment. Use a production WSGI server instead.[0m
 * Running on http://127.0.0.1:5000
[2023-06-19 18:54:36,965] INFO in _internal: [33mPress CTRL+C to quit[0m
[2023-06-19 18:55:01,908] INFO in routes: Email verified for user: Selam10
[2023-06-19 18:55:01,910] INFO in _internal: 127.0.0.1 - - [19/Jun/2023 18:55:01] "[32mGET /verify/IlNlbGFtMTAi.ZJB5vw.kD5LrlE8K5V0R4X6dLxoodZO13U HTTP/1.1[0m" 302 -
[2023-06-19 18:55:01,947] INFO in _internal: 127.0.0.1 - - [19/Jun/2023 18:55:01] "GET /login HTTP/1.1" 200 -
[2023-06-19 18:55:25,570] INFO in _internal: 127.0.0.1 - - [19/Jun/2023 18:55:25] "[32mPOST /login HTTP/1.1[0m" 302 -
[2023-06-19 18:55:25,878] INFO in _internal: 127.0.0.1 - - [19/Jun/2023 18:55:25] "GET /login HTTP/1.1" 200 -
[2023-06-19 18:55:51,067] ERROR in routes: Invalid credentials entered for user: Selam10
[2023-06-19 18:55:51,068] INFO in _internal: 127.0.0.1 - - [19/Jun/2023 18:55:51] "[32mPOST /login HTTP/1.1[0m" 302 -
[2023-06-19 18:55:51,077] INFO in _internal: 127.0.0.1 - - [19/Jun/2023 18:55:51] "GET /login HTTP/1.1" 200 -
[2023-06-19 18:56:14,022] INFO in routes: User logged in: Selam10
[2023-06-19 18:56:14,024] INFO in _internal: 127.0.0.1 - - [19/Jun/2023 18:56:14] "[32mPOST /login HTTP/1.1[0m" 302 -
[2023-06-19 18:56:14,059] INFO in _internal: 127.0.0.1 - - [19/Jun/2023 18:56:14] "GET /dashboard HTTP/1.1" 200 -
[2023-06-19 18:56:23,361] INFO in routes: User logged out: Selam10
[2023-06-19 18:56:23,363] INFO in _internal: 127.0.0.1 - - [19/Jun/2023 18:56:23] "[32mGET /logout HTTP/1.1[0m" 302 -
[2023-06-19 18:56:23,666] INFO in _internal: 127.0.0.1 - - [19/Jun/2023 18:56:23] "GET / HTTP/1.1" 200 -
[2023-06-19 18:56:25,942] INFO in _internal: 127.0.0.1 - - [19/Jun/2023 18:56:25] "GET /register HTTP/1.1" 200 -
[2023-06-19 18:56:57,645] ERROR in app: Exception on /register [POST]
Traceback (most recent call last):
  File "C:\Users\sesel\OneDrive\Desktop\Projects\secure-web-app\venv\Lib\site-packages\sqlalchemy\engine\base.py", line 1968, in _exec_single_context
    self.dialect.do_execute(
  File "C:\Users\sesel\OneDrive\Desktop\Projects\secure-web-app\venv\Lib\site-packages\sqlalchemy\engine\default.py", line 920, in do_execute
    cursor.execute(statement, parameters)
sqlite3.IntegrityError: UNIQUE constraint failed: user.name

The above exception was the direct cause of the following exception:

Traceback (most recent call last):
  File "C:\Users\sesel\OneDrive\Desktop\Projects\secure-web-app\venv\Lib\site-packages\flask\app.py", line 2190, in wsgi_app
    response = self.full_dispatch_request()
               ^^^^^^^^^^^^^^^^^^^^^^^^^^^^
  File "C:\Users\sesel\OneDrive\Desktop\Projects\secure-web-app\venv\Lib\site-packages\flask\app.py", line 1486, in full_dispatch_request
    rv = self.handle_user_exception(e)
         ^^^^^^^^^^^^^^^^^^^^^^^^^^^^^
  File "C:\Users\sesel\OneDrive\Desktop\Projects\secure-web-app\venv\Lib\site-packages\flask\app.py", line 1484, in full_dispatch_request
    rv = self.dispatch_request()
         ^^^^^^^^^^^^^^^^^^^^^^^
  File "C:\Users\sesel\OneDrive\Desktop\Projects\secure-web-app\venv\Lib\site-packages\flask\app.py", line 1469, in dispatch_request
    return self.ensure_sync(self.view_functions[rule.endpoint])(**view_args)
           ^^^^^^^^^^^^^^^^^^^^^^^^^^^^^^^^^^^^^^^^^^^^^^^^^^^^^^^^^^^^^^^^^
  File "C:\Users\sesel\OneDrive\Desktop\Projects\secure-web-app\app\routes.py", line 114, in register
    user.save()
  File "C:\Users\sesel\OneDrive\Desktop\Projects\secure-web-app\app\models.py", line 36, in save
    db.session.commit()
  File "C:\Users\sesel\OneDrive\Desktop\Projects\secure-web-app\venv\Lib\site-packages\sqlalchemy\orm\scoping.py", line 553, in commit
    return self._proxied.commit()
           ^^^^^^^^^^^^^^^^^^^^^^
  File "C:\Users\sesel\OneDrive\Desktop\Projects\secure-web-app\venv\Lib\site-packages\sqlalchemy\orm\session.py", line 1906, in commit
    trans.commit(_to_root=True)
  File "<string>", line 2, in commit
  File "C:\Users\sesel\OneDrive\Desktop\Projects\secure-web-app\venv\Lib\site-packages\sqlalchemy\orm\state_changes.py", line 137, in _go
    ret_value = fn(self, *arg, **kw)
                ^^^^^^^^^^^^^^^^^^^^
  File "C:\Users\sesel\OneDrive\Desktop\Projects\secure-web-app\venv\Lib\site-packages\sqlalchemy\orm\session.py", line 1221, in commit
    self._prepare_impl()
  File "<string>", line 2, in _prepare_impl
  File "C:\Users\sesel\OneDrive\Desktop\Projects\secure-web-app\venv\Lib\site-packages\sqlalchemy\orm\state_changes.py", line 137, in _go
    ret_value = fn(self, *arg, **kw)
                ^^^^^^^^^^^^^^^^^^^^
  File "C:\Users\sesel\OneDrive\Desktop\Projects\secure-web-app\venv\Lib\site-packages\sqlalchemy\orm\session.py", line 1196, in _prepare_impl
    self.session.flush()
  File "C:\Users\sesel\OneDrive\Desktop\Projects\secure-web-app\venv\Lib\site-packages\sqlalchemy\orm\session.py", line 4154, in flush
    self._flush(objects)
  File "C:\Users\sesel\OneDrive\Desktop\Projects\secure-web-app\venv\Lib\site-packages\sqlalchemy\orm\session.py", line 4290, in _flush
    with util.safe_reraise():
  File "C:\Users\sesel\OneDrive\Desktop\Projects\secure-web-app\venv\Lib\site-packages\sqlalchemy\util\langhelpers.py", line 147, in __exit__
    raise exc_value.with_traceback(exc_tb)
  File "C:\Users\sesel\OneDrive\Desktop\Projects\secure-web-app\venv\Lib\site-packages\sqlalchemy\orm\session.py", line 4251, in _flush
    flush_context.execute()
  File "C:\Users\sesel\OneDrive\Desktop\Projects\secure-web-app\venv\Lib\site-packages\sqlalchemy\orm\unitofwork.py", line 467, in execute
    rec.execute(self)
  File "C:\Users\sesel\OneDrive\Desktop\Projects\secure-web-app\venv\Lib\site-packages\sqlalchemy\orm\unitofwork.py", line 644, in execute
    util.preloaded.orm_persistence.save_obj(
  File "C:\Users\sesel\OneDrive\Desktop\Projects\secure-web-app\venv\Lib\site-packages\sqlalchemy\orm\persistence.py", line 93, in save_obj
    _emit_insert_statements(
  File "C:\Users\sesel\OneDrive\Desktop\Projects\secure-web-app\venv\Lib\site-packages\sqlalchemy\orm\persistence.py", line 1223, in _emit_insert_statements
    result = connection.execute(
             ^^^^^^^^^^^^^^^^^^^
  File "C:\Users\sesel\OneDrive\Desktop\Projects\secure-web-app\venv\Lib\site-packages\sqlalchemy\engine\base.py", line 1413, in execute
    return meth(
           ^^^^^
  File "C:\Users\sesel\OneDrive\Desktop\Projects\secure-web-app\venv\Lib\site-packages\sqlalchemy\sql\elements.py", line 483, in _execute_on_connection
    return connection._execute_clauseelement(
           ^^^^^^^^^^^^^^^^^^^^^^^^^^^^^^^^^^
  File "C:\Users\sesel\OneDrive\Desktop\Projects\secure-web-app\venv\Lib\site-packages\sqlalchemy\engine\base.py", line 1637, in _execute_clauseelement
    ret = self._execute_context(
          ^^^^^^^^^^^^^^^^^^^^^^
  File "C:\Users\sesel\OneDrive\Desktop\Projects\secure-web-app\venv\Lib\site-packages\sqlalchemy\engine\base.py", line 1846, in _execute_context
    return self._exec_single_context(
           ^^^^^^^^^^^^^^^^^^^^^^^^^^
  File "C:\Users\sesel\OneDrive\Desktop\Projects\secure-web-app\venv\Lib\site-packages\sqlalchemy\engine\base.py", line 1987, in _exec_single_context
    self._handle_dbapi_exception(
  File "C:\Users\sesel\OneDrive\Desktop\Projects\secure-web-app\venv\Lib\site-packages\sqlalchemy\engine\base.py", line 2344, in _handle_dbapi_exception
    raise sqlalchemy_exception.with_traceback(exc_info[2]) from e
  File "C:\Users\sesel\OneDrive\Desktop\Projects\secure-web-app\venv\Lib\site-packages\sqlalchemy\engine\base.py", line 1968, in _exec_single_context
    self.dialect.do_execute(
  File "C:\Users\sesel\OneDrive\Desktop\Projects\secure-web-app\venv\Lib\site-packages\sqlalchemy\engine\default.py", line 920, in do_execute
    cursor.execute(statement, parameters)
sqlalchemy.exc.IntegrityError: (sqlite3.IntegrityError) UNIQUE constraint failed: user.name
[SQL: INSERT INTO user (username, name, email, password, is_verified, is_blocked, registered_at, is_admin) VALUES (?, ?, ?, ?, ?, ?, ?, ?)]
[parameters: ('Selam11', 'Selamawit Elias', 'se.selamawit.elias@gmail.com', 'pbkdf2:sha256:600000$zGyD1MgDqYxjXge5$358bb41c6a238f17581d8080bb40e32a0ba3b3a84e03cdaedb216bbf2bf320ba', 0, 0, '2023-06-19 15:56:57.644962', 0)]
(Background on this error at: https://sqlalche.me/e/20/gkpj)
[2023-06-19 18:56:57,677] INFO in _internal: 127.0.0.1 - - [19/Jun/2023 18:56:57] "[35m[1mPOST /register HTTP/1.1[0m" 500 -
[2023-06-19 18:56:57,840] INFO in _internal: 127.0.0.1 - - [19/Jun/2023 18:56:57] "[36mGET /static/images/500.jpg HTTP/1.1[0m" 304 -
[2023-06-19 18:58:36,944] INFO in routes: User registered: Selam11
[2023-06-19 18:58:36,945] INFO in _internal: 127.0.0.1 - - [19/Jun/2023 18:58:36] "[32mPOST /register HTTP/1.1[0m" 302 -
[2023-06-19 18:58:36,956] INFO in _internal: 127.0.0.1 - - [19/Jun/2023 18:58:36] "GET /login HTTP/1.1" 200 -
[2023-06-19 18:58:57,558] INFO in routes: Email verified for user: Selam11
[2023-06-19 18:58:57,559] INFO in _internal: 127.0.0.1 - - [19/Jun/2023 18:58:57] "[32mGET /verify/IlNlbGFtMTEi.ZJB7KA.drSxYb_sYoJ4GH_56v3VOxbr3NU HTTP/1.1[0m" 302 -
[2023-06-19 18:58:57,568] INFO in _internal: 127.0.0.1 - - [19/Jun/2023 18:58:57] "GET /login HTTP/1.1" 200 -
[2023-06-19 18:59:27,749] INFO in routes: User logged in: Selam11
[2023-06-19 18:59:27,751] INFO in _internal: 127.0.0.1 - - [19/Jun/2023 18:59:27] "[32mPOST /login HTTP/1.1[0m" 302 -
[2023-06-19 18:59:27,762] INFO in _internal: 127.0.0.1 - - [19/Jun/2023 18:59:27] "GET /dashboard HTTP/1.1" 200 -
[2023-06-19 19:01:02,306] INFO in _internal: 127.0.0.1 - - [19/Jun/2023 19:01:02] "GET /dashboard HTTP/1.1" 200 -
[2023-06-19 19:01:04,799] INFO in _internal: 127.0.0.1 - - [19/Jun/2023 19:01:04] "GET /secret HTTP/1.1" 200 -
[2023-06-19 19:01:11,037] INFO in _internal: 127.0.0.1 - - [19/Jun/2023 19:01:11] "[32mPOST /admin/user/2/toggle_status HTTP/1.1[0m" 302 -
[2023-06-19 19:01:11,336] INFO in _internal: 127.0.0.1 - - [19/Jun/2023 19:01:11] "GET /secret HTTP/1.1" 200 -
[2023-06-19 19:01:21,420] INFO in _internal: 127.0.0.1 - - [19/Jun/2023 19:01:21] "GET /honeypots HTTP/1.1" 200 -
[2023-06-19 19:01:45,662] INFO in _internal: 127.0.0.1 - - [19/Jun/2023 19:01:45] "GET /admin_login HTTP/1.1" 200 -
[2023-06-19 19:02:15,539] INFO in _internal: 127.0.0.1 - - [19/Jun/2023 19:02:15] "POST /admin_login HTTP/1.1" 200 -
[2023-06-19 19:02:22,895] INFO in _internal: 127.0.0.1 - - [19/Jun/2023 19:02:22] "GET /honeypots HTTP/1.1" 200 -
[2023-06-19 19:02:38,388] INFO in _internal: 127.0.0.1 - - [19/Jun/2023 19:02:38] "GET /secret HTTP/1.1" 200 -
[2023-06-19 19:02:40,466] INFO in _internal: 127.0.0.1 - - [19/Jun/2023 19:02:40] "GET /dashboard HTTP/1.1" 200 -
[2023-06-19 19:02:42,896] INFO in _internal: 127.0.0.1 - - [19/Jun/2023 19:02:42] "GET /dashboard HTTP/1.1" 200 -
[2023-06-19 21:52:29,228] INFO in _internal: [31m[1mWARNING: This is a development server. Do not use it in a production deployment. Use a production WSGI server instead.[0m
 * Running on http://127.0.0.1:5000
[2023-06-19 21:52:29,228] INFO in _internal: [33mPress CTRL+C to quit[0m
[2023-06-19 21:54:15,857] INFO in _internal: 127.0.0.1 - - [19/Jun/2023 21:54:15] "GET / HTTP/1.1" 200 -
[2023-06-19 21:54:16,162] INFO in _internal: 127.0.0.1 - - [19/Jun/2023 21:54:16] "[33mGET /favicon.ico HTTP/1.1[0m" 404 -
[2023-06-19 21:54:21,706] INFO in _internal: 127.0.0.1 - - [19/Jun/2023 21:54:21] "GET /login HTTP/1.1" 200 -
[2023-06-19 22:37:19,417] INFO in _internal: [31m[1mWARNING: This is a development server. Do not use it in a production deployment. Use a production WSGI server instead.[0m
 * Running on http://127.0.0.1:5000
[2023-06-19 22:37:19,418] INFO in _internal: [33mPress CTRL+C to quit[0m
[2023-06-19 22:37:35,008] INFO in _internal: 127.0.0.1 - - [19/Jun/2023 22:37:35] "GET /login HTTP/1.1" 200 -
[2023-06-19 22:38:09,026] INFO in _internal: 127.0.0.1 - - [19/Jun/2023 22:38:09] "GET /login HTTP/1.1" 200 -
[2023-06-19 22:39:18,185] ERROR in app: Exception on /login [POST]
Traceback (most recent call last):
  File "C:\Users\sesel\AppData\Local\Programs\Python\Python311\Lib\urllib\request.py", line 1348, in do_open
    h.request(req.get_method(), req.selector, req.data, headers,
  File "C:\Users\sesel\AppData\Local\Programs\Python\Python311\Lib\http\client.py", line 1282, in request
    self._send_request(method, url, body, headers, encode_chunked)
  File "C:\Users\sesel\AppData\Local\Programs\Python\Python311\Lib\http\client.py", line 1328, in _send_request
    self.endheaders(body, encode_chunked=encode_chunked)
  File "C:\Users\sesel\AppData\Local\Programs\Python\Python311\Lib\http\client.py", line 1277, in endheaders
    self._send_output(message_body, encode_chunked=encode_chunked)
  File "C:\Users\sesel\AppData\Local\Programs\Python\Python311\Lib\http\client.py", line 1037, in _send_output
    self.send(msg)
  File "C:\Users\sesel\AppData\Local\Programs\Python\Python311\Lib\http\client.py", line 975, in send
    self.connect()
  File "C:\Users\sesel\AppData\Local\Programs\Python\Python311\Lib\http\client.py", line 1447, in connect
    super().connect()
  File "C:\Users\sesel\AppData\Local\Programs\Python\Python311\Lib\http\client.py", line 941, in connect
    self.sock = self._create_connection(
                ^^^^^^^^^^^^^^^^^^^^^^^^
  File "C:\Users\sesel\AppData\Local\Programs\Python\Python311\Lib\socket.py", line 851, in create_connection
    raise exceptions[0]
  File "C:\Users\sesel\AppData\Local\Programs\Python\Python311\Lib\socket.py", line 836, in create_connection
    sock.connect(sa)
TimeoutError: [WinError 10060] A connection attempt failed because the connected party did not properly respond after a period of time, or established connection failed because connected host has failed to respond

During handling of the above exception, another exception occurred:

Traceback (most recent call last):
  File "C:\Users\sesel\OneDrive\Desktop\Projects\secure-web-app\venv\Lib\site-packages\flask\app.py", line 2190, in wsgi_app
    response = self.full_dispatch_request()
               ^^^^^^^^^^^^^^^^^^^^^^^^^^^^
  File "C:\Users\sesel\OneDrive\Desktop\Projects\secure-web-app\venv\Lib\site-packages\flask\app.py", line 1486, in full_dispatch_request
    rv = self.handle_user_exception(e)
         ^^^^^^^^^^^^^^^^^^^^^^^^^^^^^
  File "C:\Users\sesel\OneDrive\Desktop\Projects\secure-web-app\venv\Lib\site-packages\flask\app.py", line 1484, in full_dispatch_request
    rv = self.dispatch_request()
         ^^^^^^^^^^^^^^^^^^^^^^^
  File "C:\Users\sesel\OneDrive\Desktop\Projects\secure-web-app\venv\Lib\site-packages\flask\app.py", line 1469, in dispatch_request
    return self.ensure_sync(self.view_functions[rule.endpoint])(**view_args)
           ^^^^^^^^^^^^^^^^^^^^^^^^^^^^^^^^^^^^^^^^^^^^^^^^^^^^^^^^^^^^^^^^^
  File "C:\Users\sesel\OneDrive\Desktop\Projects\secure-web-app\app\routes.py", line 169, in login
    if form.validate_on_submit():
       ^^^^^^^^^^^^^^^^^^^^^^^^^
  File "C:\Users\sesel\OneDrive\Desktop\Projects\secure-web-app\venv\Lib\site-packages\flask_wtf\form.py", line 86, in validate_on_submit
    return self.is_submitted() and self.validate(extra_validators=extra_validators)
                                   ^^^^^^^^^^^^^^^^^^^^^^^^^^^^^^^^^^^^^^^^^^^^^^^^
  File "C:\Users\sesel\OneDrive\Desktop\Projects\secure-web-app\venv\Lib\site-packages\wtforms\form.py", line 329, in validate
    return super().validate(extra)
           ^^^^^^^^^^^^^^^^^^^^^^^
  File "C:\Users\sesel\OneDrive\Desktop\Projects\secure-web-app\venv\Lib\site-packages\wtforms\form.py", line 146, in validate
    if not field.validate(self, extra):
           ^^^^^^^^^^^^^^^^^^^^^^^^^^^
  File "C:\Users\sesel\OneDrive\Desktop\Projects\secure-web-app\venv\Lib\site-packages\wtforms\fields\core.py", line 242, in validate
    stop_validation = self._run_validation_chain(form, chain)
                      ^^^^^^^^^^^^^^^^^^^^^^^^^^^^^^^^^^^^^^^
  File "C:\Users\sesel\OneDrive\Desktop\Projects\secure-web-app\venv\Lib\site-packages\wtforms\fields\core.py", line 262, in _run_validation_chain
    validator(form, self)
  File "C:\Users\sesel\OneDrive\Desktop\Projects\secure-web-app\venv\Lib\site-packages\flask_wtf\recaptcha\validators.py", line 42, in __call__
    if not self._validate_recaptcha(response, remote_ip):
           ^^^^^^^^^^^^^^^^^^^^^^^^^^^^^^^^^^^^^^^^^^^^^
  File "C:\Users\sesel\OneDrive\Desktop\Projects\secure-web-app\venv\Lib\site-packages\flask_wtf\recaptcha\validators.py", line 61, in _validate_recaptcha
    http_response = http.urlopen(verify_server, data.encode("utf-8"))
                    ^^^^^^^^^^^^^^^^^^^^^^^^^^^^^^^^^^^^^^^^^^^^^^^^^
  File "C:\Users\sesel\AppData\Local\Programs\Python\Python311\Lib\urllib\request.py", line 216, in urlopen
    return opener.open(url, data, timeout)
           ^^^^^^^^^^^^^^^^^^^^^^^^^^^^^^^
  File "C:\Users\sesel\AppData\Local\Programs\Python\Python311\Lib\urllib\request.py", line 519, in open
    response = self._open(req, data)
               ^^^^^^^^^^^^^^^^^^^^^
  File "C:\Users\sesel\AppData\Local\Programs\Python\Python311\Lib\urllib\request.py", line 536, in _open
    result = self._call_chain(self.handle_open, protocol, protocol +
             ^^^^^^^^^^^^^^^^^^^^^^^^^^^^^^^^^^^^^^^^^^^^^^^^^^^^^^^
  File "C:\Users\sesel\AppData\Local\Programs\Python\Python311\Lib\urllib\request.py", line 496, in _call_chain
    result = func(*args)
             ^^^^^^^^^^^
  File "C:\Users\sesel\AppData\Local\Programs\Python\Python311\Lib\urllib\request.py", line 1391, in https_open
    return self.do_open(http.client.HTTPSConnection, req,
           ^^^^^^^^^^^^^^^^^^^^^^^^^^^^^^^^^^^^^^^^^^^^^^
  File "C:\Users\sesel\AppData\Local\Programs\Python\Python311\Lib\urllib\request.py", line 1351, in do_open
    raise URLError(err)
urllib.error.URLError: <urlopen error [WinError 10060] A connection attempt failed because the connected party did not properly respond after a period of time, or established connection failed because connected host has failed to respond>
[2023-06-19 22:39:18,209] INFO in _internal: 127.0.0.1 - - [19/Jun/2023 22:39:18] "[35m[1mPOST /login HTTP/1.1[0m" 500 -
[2023-06-19 22:39:18,324] INFO in _internal: 127.0.0.1 - - [19/Jun/2023 22:39:18] "[36mGET /static/images/500.jpg HTTP/1.1[0m" 304 -
[2023-06-19 22:40:25,245] INFO in routes: User logged in: Selam10
[2023-06-19 22:40:25,247] INFO in _internal: 127.0.0.1 - - [19/Jun/2023 22:40:25] "[32mPOST /login HTTP/1.1[0m" 302 -
[2023-06-19 22:40:25,269] INFO in _internal: 127.0.0.1 - - [19/Jun/2023 22:40:25] "GET /dashboard HTTP/1.1" 200 -
[2023-06-19 22:43:41,242] INFO in _internal: 127.0.0.1 - - [19/Jun/2023 22:43:41] "[32mGET /login HTTP/1.1[0m" 302 -
[2023-06-19 22:43:41,262] INFO in _internal: 127.0.0.1 - - [19/Jun/2023 22:43:41] "GET /dashboard HTTP/1.1" 200 -
[2023-06-19 22:43:43,228] INFO in _internal: 127.0.0.1 - - [19/Jun/2023 22:43:43] "GET / HTTP/1.1" 200 -
[2023-06-19 22:43:48,073] INFO in routes: User logged out: Selam10
[2023-06-19 22:43:48,074] INFO in _internal: 127.0.0.1 - - [19/Jun/2023 22:43:48] "[32mGET /logout HTTP/1.1[0m" 302 -
[2023-06-19 22:43:48,380] INFO in _internal: 127.0.0.1 - - [19/Jun/2023 22:43:48] "GET / HTTP/1.1" 200 -
[2023-06-19 22:43:50,332] INFO in _internal: 127.0.0.1 - - [19/Jun/2023 22:43:50] "GET /login HTTP/1.1" 200 -
[2023-06-19 22:44:39,442] ERROR in app: Exception on /login [POST]
Traceback (most recent call last):
  File "C:\Users\sesel\AppData\Local\Programs\Python\Python311\Lib\urllib\request.py", line 1348, in do_open
    h.request(req.get_method(), req.selector, req.data, headers,
  File "C:\Users\sesel\AppData\Local\Programs\Python\Python311\Lib\http\client.py", line 1282, in request
    self._send_request(method, url, body, headers, encode_chunked)
  File "C:\Users\sesel\AppData\Local\Programs\Python\Python311\Lib\http\client.py", line 1328, in _send_request
    self.endheaders(body, encode_chunked=encode_chunked)
  File "C:\Users\sesel\AppData\Local\Programs\Python\Python311\Lib\http\client.py", line 1277, in endheaders
    self._send_output(message_body, encode_chunked=encode_chunked)
  File "C:\Users\sesel\AppData\Local\Programs\Python\Python311\Lib\http\client.py", line 1037, in _send_output
    self.send(msg)
  File "C:\Users\sesel\AppData\Local\Programs\Python\Python311\Lib\http\client.py", line 975, in send
    self.connect()
  File "C:\Users\sesel\AppData\Local\Programs\Python\Python311\Lib\http\client.py", line 1447, in connect
    super().connect()
  File "C:\Users\sesel\AppData\Local\Programs\Python\Python311\Lib\http\client.py", line 941, in connect
    self.sock = self._create_connection(
                ^^^^^^^^^^^^^^^^^^^^^^^^
  File "C:\Users\sesel\AppData\Local\Programs\Python\Python311\Lib\socket.py", line 827, in create_connection
    for res in getaddrinfo(host, port, 0, SOCK_STREAM):
               ^^^^^^^^^^^^^^^^^^^^^^^^^^^^^^^^^^^^^^^
  File "C:\Users\sesel\AppData\Local\Programs\Python\Python311\Lib\socket.py", line 962, in getaddrinfo
    for res in _socket.getaddrinfo(host, port, family, type, proto, flags):
               ^^^^^^^^^^^^^^^^^^^^^^^^^^^^^^^^^^^^^^^^^^^^^^^^^^^^^^^^^^^
socket.gaierror: [Errno 11001] getaddrinfo failed

During handling of the above exception, another exception occurred:

Traceback (most recent call last):
  File "C:\Users\sesel\OneDrive\Desktop\Projects\secure-web-app\venv\Lib\site-packages\flask\app.py", line 2190, in wsgi_app
    response = self.full_dispatch_request()
               ^^^^^^^^^^^^^^^^^^^^^^^^^^^^
  File "C:\Users\sesel\OneDrive\Desktop\Projects\secure-web-app\venv\Lib\site-packages\flask\app.py", line 1486, in full_dispatch_request
    rv = self.handle_user_exception(e)
         ^^^^^^^^^^^^^^^^^^^^^^^^^^^^^
  File "C:\Users\sesel\OneDrive\Desktop\Projects\secure-web-app\venv\Lib\site-packages\flask\app.py", line 1484, in full_dispatch_request
    rv = self.dispatch_request()
         ^^^^^^^^^^^^^^^^^^^^^^^
  File "C:\Users\sesel\OneDrive\Desktop\Projects\secure-web-app\venv\Lib\site-packages\flask\app.py", line 1469, in dispatch_request
    return self.ensure_sync(self.view_functions[rule.endpoint])(**view_args)
           ^^^^^^^^^^^^^^^^^^^^^^^^^^^^^^^^^^^^^^^^^^^^^^^^^^^^^^^^^^^^^^^^^
  File "C:\Users\sesel\OneDrive\Desktop\Projects\secure-web-app\app\routes.py", line 169, in login
    if form.validate_on_submit():
       ^^^^^^^^^^^^^^^^^^^^^^^^^
  File "C:\Users\sesel\OneDrive\Desktop\Projects\secure-web-app\venv\Lib\site-packages\flask_wtf\form.py", line 86, in validate_on_submit
    return self.is_submitted() and self.validate(extra_validators=extra_validators)
                                   ^^^^^^^^^^^^^^^^^^^^^^^^^^^^^^^^^^^^^^^^^^^^^^^^
  File "C:\Users\sesel\OneDrive\Desktop\Projects\secure-web-app\venv\Lib\site-packages\wtforms\form.py", line 329, in validate
    return super().validate(extra)
           ^^^^^^^^^^^^^^^^^^^^^^^
  File "C:\Users\sesel\OneDrive\Desktop\Projects\secure-web-app\venv\Lib\site-packages\wtforms\form.py", line 146, in validate
    if not field.validate(self, extra):
           ^^^^^^^^^^^^^^^^^^^^^^^^^^^
  File "C:\Users\sesel\OneDrive\Desktop\Projects\secure-web-app\venv\Lib\site-packages\wtforms\fields\core.py", line 242, in validate
    stop_validation = self._run_validation_chain(form, chain)
                      ^^^^^^^^^^^^^^^^^^^^^^^^^^^^^^^^^^^^^^^
  File "C:\Users\sesel\OneDrive\Desktop\Projects\secure-web-app\venv\Lib\site-packages\wtforms\fields\core.py", line 262, in _run_validation_chain
    validator(form, self)
  File "C:\Users\sesel\OneDrive\Desktop\Projects\secure-web-app\venv\Lib\site-packages\flask_wtf\recaptcha\validators.py", line 42, in __call__
    if not self._validate_recaptcha(response, remote_ip):
           ^^^^^^^^^^^^^^^^^^^^^^^^^^^^^^^^^^^^^^^^^^^^^
  File "C:\Users\sesel\OneDrive\Desktop\Projects\secure-web-app\venv\Lib\site-packages\flask_wtf\recaptcha\validators.py", line 61, in _validate_recaptcha
    http_response = http.urlopen(verify_server, data.encode("utf-8"))
                    ^^^^^^^^^^^^^^^^^^^^^^^^^^^^^^^^^^^^^^^^^^^^^^^^^
  File "C:\Users\sesel\AppData\Local\Programs\Python\Python311\Lib\urllib\request.py", line 216, in urlopen
    return opener.open(url, data, timeout)
           ^^^^^^^^^^^^^^^^^^^^^^^^^^^^^^^
  File "C:\Users\sesel\AppData\Local\Programs\Python\Python311\Lib\urllib\request.py", line 519, in open
    response = self._open(req, data)
               ^^^^^^^^^^^^^^^^^^^^^
  File "C:\Users\sesel\AppData\Local\Programs\Python\Python311\Lib\urllib\request.py", line 536, in _open
    result = self._call_chain(self.handle_open, protocol, protocol +
             ^^^^^^^^^^^^^^^^^^^^^^^^^^^^^^^^^^^^^^^^^^^^^^^^^^^^^^^
  File "C:\Users\sesel\AppData\Local\Programs\Python\Python311\Lib\urllib\request.py", line 496, in _call_chain
    result = func(*args)
             ^^^^^^^^^^^
  File "C:\Users\sesel\AppData\Local\Programs\Python\Python311\Lib\urllib\request.py", line 1391, in https_open
    return self.do_open(http.client.HTTPSConnection, req,
           ^^^^^^^^^^^^^^^^^^^^^^^^^^^^^^^^^^^^^^^^^^^^^^
  File "C:\Users\sesel\AppData\Local\Programs\Python\Python311\Lib\urllib\request.py", line 1351, in do_open
    raise URLError(err)
urllib.error.URLError: <urlopen error [Errno 11001] getaddrinfo failed>
[2023-06-19 22:44:39,448] INFO in _internal: 127.0.0.1 - - [19/Jun/2023 22:44:39] "[35m[1mPOST /login HTTP/1.1[0m" 500 -
[2023-06-19 22:44:39,501] INFO in _internal: 127.0.0.1 - - [19/Jun/2023 22:44:39] "[36mGET /static/images/500.jpg HTTP/1.1[0m" 304 -
[2023-06-19 22:45:02,411] INFO in routes: User logged in: Selam11
[2023-06-19 22:45:02,411] INFO in _internal: 127.0.0.1 - - [19/Jun/2023 22:45:02] "[32mPOST /login HTTP/1.1[0m" 302 -
[2023-06-19 22:45:02,421] INFO in _internal: 127.0.0.1 - - [19/Jun/2023 22:45:02] "GET /dashboard HTTP/1.1" 200 -
[2023-06-20 04:31:57,565] INFO in _internal: [31m[1mWARNING: This is a development server. Do not use it in a production deployment. Use a production WSGI server instead.[0m
 * Running on http://127.0.0.1:5000
[2023-06-20 04:31:57,565] INFO in _internal: [33mPress CTRL+C to quit[0m
[2023-06-20 04:32:15,071] INFO in _internal: 127.0.0.1 - - [20/Jun/2023 04:32:15] "GET / HTTP/1.1" 200 -
[2023-06-20 04:32:15,465] INFO in _internal: 127.0.0.1 - - [20/Jun/2023 04:32:15] "[33mGET /favicon.ico HTTP/1.1[0m" 404 -
[2023-06-20 04:35:19,277] INFO in _internal: 127.0.0.1 - - [20/Jun/2023 04:35:19] "GET / HTTP/1.1" 200 -
[2023-06-20 04:35:25,034] INFO in _internal: 127.0.0.1 - - [20/Jun/2023 04:35:25] "GET / HTTP/1.1" 200 -
[2023-06-20 04:36:08,987] INFO in _internal: 127.0.0.1 - - [20/Jun/2023 04:36:08] "GET /register HTTP/1.1" 200 -
[2023-06-20 04:50:50,800] INFO in _internal: [31m[1mWARNING: This is a development server. Do not use it in a production deployment. Use a production WSGI server instead.[0m
 * Running on http://127.0.0.1:5000
[2023-06-20 04:50:50,800] INFO in _internal: [33mPress CTRL+C to quit[0m
[2023-06-20 04:50:56,650] INFO in _internal: 127.0.0.1 - - [20/Jun/2023 04:50:56] "GET /register HTTP/1.1" 200 -
[2023-06-20 04:51:49,231] ERROR in app: Exception on /register [POST]
Traceback (most recent call last):
  File "C:\Users\sesel\OneDrive\Desktop\Projects\secure-web-app\venv\Lib\site-packages\flask\app.py", line 2190, in wsgi_app
    response = self.full_dispatch_request()
               ^^^^^^^^^^^^^^^^^^^^^^^^^^^^
  File "C:\Users\sesel\OneDrive\Desktop\Projects\secure-web-app\venv\Lib\site-packages\flask\app.py", line 1486, in full_dispatch_request
    rv = self.handle_user_exception(e)
         ^^^^^^^^^^^^^^^^^^^^^^^^^^^^^
  File "C:\Users\sesel\OneDrive\Desktop\Projects\secure-web-app\venv\Lib\site-packages\flask\app.py", line 1484, in full_dispatch_request
    rv = self.dispatch_request()
         ^^^^^^^^^^^^^^^^^^^^^^^
  File "C:\Users\sesel\OneDrive\Desktop\Projects\secure-web-app\venv\Lib\site-packages\flask\app.py", line 1469, in dispatch_request
    return self.ensure_sync(self.view_functions[rule.endpoint])(**view_args)
           ^^^^^^^^^^^^^^^^^^^^^^^^^^^^^^^^^^^^^^^^^^^^^^^^^^^^^^^^^^^^^^^^^
  File "C:\Users\sesel\OneDrive\Desktop\Projects\secure-web-app\app\routes.py", line 126, in register
    send_verification_email(email, verification_link)
  File "C:\Users\sesel\OneDrive\Desktop\Projects\secure-web-app\app\routes.py", line 77, in send_verification_email
    mail.send(msg)
  File "C:\Users\sesel\OneDrive\Desktop\Projects\secure-web-app\venv\Lib\site-packages\flask_mail.py", line 491, in send
    with self.connect() as connection:
  File "C:\Users\sesel\OneDrive\Desktop\Projects\secure-web-app\venv\Lib\site-packages\flask_mail.py", line 144, in __enter__
    self.host = self.configure_host()
                ^^^^^^^^^^^^^^^^^^^^^
  File "C:\Users\sesel\OneDrive\Desktop\Projects\secure-web-app\venv\Lib\site-packages\flask_mail.py", line 158, in configure_host
    host = smtplib.SMTP(self.mail.server, self.mail.port)
           ^^^^^^^^^^^^^^^^^^^^^^^^^^^^^^^^^^^^^^^^^^^^^^
  File "C:\Users\sesel\AppData\Local\Programs\Python\Python311\Lib\smtplib.py", line 255, in __init__
    (code, msg) = self.connect(host, port)
                  ^^^^^^^^^^^^^^^^^^^^^^^^
  File "C:\Users\sesel\AppData\Local\Programs\Python\Python311\Lib\smtplib.py", line 343, in connect
    (code, msg) = self.getreply()
                  ^^^^^^^^^^^^^^^
  File "C:\Users\sesel\AppData\Local\Programs\Python\Python311\Lib\smtplib.py", line 405, in getreply
    raise SMTPServerDisconnected("Connection unexpectedly closed")
smtplib.SMTPServerDisconnected: Connection unexpectedly closed
[2023-06-20 04:51:49,246] INFO in _internal: 127.0.0.1 - - [20/Jun/2023 04:51:49] "[35m[1mPOST /register HTTP/1.1[0m" 500 -
[2023-06-20 04:51:49,438] INFO in _internal: 127.0.0.1 - - [20/Jun/2023 04:51:49] "[36mGET /static/images/500.jpg HTTP/1.1[0m" 304 -
[2023-06-20 04:52:46,455] INFO in _internal: 127.0.0.1 - - [20/Jun/2023 04:52:46] "GET /register HTTP/1.1" 200 -
[2023-06-20 04:53:11,601] ERROR in app: Exception on /register [POST]
Traceback (most recent call last):
  File "C:\Users\sesel\OneDrive\Desktop\Projects\secure-web-app\venv\Lib\site-packages\flask\app.py", line 2190, in wsgi_app
    response = self.full_dispatch_request()
               ^^^^^^^^^^^^^^^^^^^^^^^^^^^^
  File "C:\Users\sesel\OneDrive\Desktop\Projects\secure-web-app\venv\Lib\site-packages\flask\app.py", line 1486, in full_dispatch_request
    rv = self.handle_user_exception(e)
         ^^^^^^^^^^^^^^^^^^^^^^^^^^^^^
  File "C:\Users\sesel\OneDrive\Desktop\Projects\secure-web-app\venv\Lib\site-packages\flask\app.py", line 1484, in full_dispatch_request
    rv = self.dispatch_request()
         ^^^^^^^^^^^^^^^^^^^^^^^
  File "C:\Users\sesel\OneDrive\Desktop\Projects\secure-web-app\venv\Lib\site-packages\flask\app.py", line 1469, in dispatch_request
    return self.ensure_sync(self.view_functions[rule.endpoint])(**view_args)
           ^^^^^^^^^^^^^^^^^^^^^^^^^^^^^^^^^^^^^^^^^^^^^^^^^^^^^^^^^^^^^^^^^
  File "C:\Users\sesel\OneDrive\Desktop\Projects\secure-web-app\app\routes.py", line 126, in register
    send_verification_email(email, verification_link)
  File "C:\Users\sesel\OneDrive\Desktop\Projects\secure-web-app\app\routes.py", line 77, in send_verification_email
    mail.send(msg)
  File "C:\Users\sesel\OneDrive\Desktop\Projects\secure-web-app\venv\Lib\site-packages\flask_mail.py", line 491, in send
    with self.connect() as connection:
  File "C:\Users\sesel\OneDrive\Desktop\Projects\secure-web-app\venv\Lib\site-packages\flask_mail.py", line 144, in __enter__
    self.host = self.configure_host()
                ^^^^^^^^^^^^^^^^^^^^^
  File "C:\Users\sesel\OneDrive\Desktop\Projects\secure-web-app\venv\Lib\site-packages\flask_mail.py", line 158, in configure_host
    host = smtplib.SMTP(self.mail.server, self.mail.port)
           ^^^^^^^^^^^^^^^^^^^^^^^^^^^^^^^^^^^^^^^^^^^^^^
  File "C:\Users\sesel\AppData\Local\Programs\Python\Python311\Lib\smtplib.py", line 255, in __init__
    (code, msg) = self.connect(host, port)
                  ^^^^^^^^^^^^^^^^^^^^^^^^
  File "C:\Users\sesel\AppData\Local\Programs\Python\Python311\Lib\smtplib.py", line 343, in connect
    (code, msg) = self.getreply()
                  ^^^^^^^^^^^^^^^
  File "C:\Users\sesel\AppData\Local\Programs\Python\Python311\Lib\smtplib.py", line 405, in getreply
    raise SMTPServerDisconnected("Connection unexpectedly closed")
smtplib.SMTPServerDisconnected: Connection unexpectedly closed
[2023-06-20 04:53:11,604] INFO in _internal: 127.0.0.1 - - [20/Jun/2023 04:53:11] "[35m[1mPOST /register HTTP/1.1[0m" 500 -
[2023-06-20 04:53:11,661] INFO in _internal: 127.0.0.1 - - [20/Jun/2023 04:53:11] "[36mGET /static/images/500.jpg HTTP/1.1[0m" 304 -
[2023-06-20 04:54:08,996] INFO in _internal: [31m[1mWARNING: This is a development server. Do not use it in a production deployment. Use a production WSGI server instead.[0m
 * Running on http://127.0.0.1:5000
[2023-06-20 04:54:08,997] INFO in _internal: [33mPress CTRL+C to quit[0m
[2023-06-20 04:54:25,948] INFO in _internal: 127.0.0.1 - - [20/Jun/2023 04:54:25] "GET /register HTTP/1.1" 200 -
[2023-06-20 04:55:24,885] ERROR in app: Exception on /register [POST]
Traceback (most recent call last):
  File "C:\Users\sesel\OneDrive\Desktop\Projects\secure-web-app\venv\Lib\site-packages\flask\app.py", line 2190, in wsgi_app
    response = self.full_dispatch_request()
               ^^^^^^^^^^^^^^^^^^^^^^^^^^^^
  File "C:\Users\sesel\OneDrive\Desktop\Projects\secure-web-app\venv\Lib\site-packages\flask\app.py", line 1486, in full_dispatch_request
    rv = self.handle_user_exception(e)
         ^^^^^^^^^^^^^^^^^^^^^^^^^^^^^
  File "C:\Users\sesel\OneDrive\Desktop\Projects\secure-web-app\venv\Lib\site-packages\flask\app.py", line 1484, in full_dispatch_request
    rv = self.dispatch_request()
         ^^^^^^^^^^^^^^^^^^^^^^^
  File "C:\Users\sesel\OneDrive\Desktop\Projects\secure-web-app\venv\Lib\site-packages\flask\app.py", line 1469, in dispatch_request
    return self.ensure_sync(self.view_functions[rule.endpoint])(**view_args)
           ^^^^^^^^^^^^^^^^^^^^^^^^^^^^^^^^^^^^^^^^^^^^^^^^^^^^^^^^^^^^^^^^^
  File "C:\Users\sesel\OneDrive\Desktop\Projects\secure-web-app\app\routes.py", line 126, in register
    send_verification_email(email, verification_link)
  File "C:\Users\sesel\OneDrive\Desktop\Projects\secure-web-app\app\routes.py", line 77, in send_verification_email
    mail.send(msg)
  File "C:\Users\sesel\OneDrive\Desktop\Projects\secure-web-app\venv\Lib\site-packages\flask_mail.py", line 491, in send
    with self.connect() as connection:
  File "C:\Users\sesel\OneDrive\Desktop\Projects\secure-web-app\venv\Lib\site-packages\flask_mail.py", line 144, in __enter__
    self.host = self.configure_host()
                ^^^^^^^^^^^^^^^^^^^^^
  File "C:\Users\sesel\OneDrive\Desktop\Projects\secure-web-app\venv\Lib\site-packages\flask_mail.py", line 158, in configure_host
    host = smtplib.SMTP(self.mail.server, self.mail.port)
           ^^^^^^^^^^^^^^^^^^^^^^^^^^^^^^^^^^^^^^^^^^^^^^
  File "C:\Users\sesel\AppData\Local\Programs\Python\Python311\Lib\smtplib.py", line 255, in __init__
    (code, msg) = self.connect(host, port)
                  ^^^^^^^^^^^^^^^^^^^^^^^^
  File "C:\Users\sesel\AppData\Local\Programs\Python\Python311\Lib\smtplib.py", line 343, in connect
    (code, msg) = self.getreply()
                  ^^^^^^^^^^^^^^^
  File "C:\Users\sesel\AppData\Local\Programs\Python\Python311\Lib\smtplib.py", line 405, in getreply
    raise SMTPServerDisconnected("Connection unexpectedly closed")
smtplib.SMTPServerDisconnected: Connection unexpectedly closed
[2023-06-20 04:55:24,899] INFO in _internal: 127.0.0.1 - - [20/Jun/2023 04:55:24] "[35m[1mPOST /register HTTP/1.1[0m" 500 -
[2023-06-20 04:55:25,070] INFO in _internal: 127.0.0.1 - - [20/Jun/2023 04:55:25] "[36mGET /static/images/500.jpg HTTP/1.1[0m" 304 -
[2023-06-20 04:57:39,591] ERROR in app: Exception on /register [POST]
Traceback (most recent call last):
  File "C:\Users\sesel\OneDrive\Desktop\Projects\secure-web-app\venv\Lib\site-packages\flask\app.py", line 2190, in wsgi_app
    response = self.full_dispatch_request()
               ^^^^^^^^^^^^^^^^^^^^^^^^^^^^
  File "C:\Users\sesel\OneDrive\Desktop\Projects\secure-web-app\venv\Lib\site-packages\flask\app.py", line 1486, in full_dispatch_request
    rv = self.handle_user_exception(e)
         ^^^^^^^^^^^^^^^^^^^^^^^^^^^^^
  File "C:\Users\sesel\OneDrive\Desktop\Projects\secure-web-app\venv\Lib\site-packages\flask\app.py", line 1484, in full_dispatch_request
    rv = self.dispatch_request()
         ^^^^^^^^^^^^^^^^^^^^^^^
  File "C:\Users\sesel\OneDrive\Desktop\Projects\secure-web-app\venv\Lib\site-packages\flask\app.py", line 1469, in dispatch_request
    return self.ensure_sync(self.view_functions[rule.endpoint])(**view_args)
           ^^^^^^^^^^^^^^^^^^^^^^^^^^^^^^^^^^^^^^^^^^^^^^^^^^^^^^^^^^^^^^^^^
  File "C:\Users\sesel\OneDrive\Desktop\Projects\secure-web-app\app\routes.py", line 126, in register
    send_verification_email(email, verification_link)
  File "C:\Users\sesel\OneDrive\Desktop\Projects\secure-web-app\app\routes.py", line 77, in send_verification_email
    mail.send(msg)
  File "C:\Users\sesel\OneDrive\Desktop\Projects\secure-web-app\venv\Lib\site-packages\flask_mail.py", line 491, in send
    with self.connect() as connection:
  File "C:\Users\sesel\OneDrive\Desktop\Projects\secure-web-app\venv\Lib\site-packages\flask_mail.py", line 144, in __enter__
    self.host = self.configure_host()
                ^^^^^^^^^^^^^^^^^^^^^
  File "C:\Users\sesel\OneDrive\Desktop\Projects\secure-web-app\venv\Lib\site-packages\flask_mail.py", line 158, in configure_host
    host = smtplib.SMTP(self.mail.server, self.mail.port)
           ^^^^^^^^^^^^^^^^^^^^^^^^^^^^^^^^^^^^^^^^^^^^^^
  File "C:\Users\sesel\AppData\Local\Programs\Python\Python311\Lib\smtplib.py", line 255, in __init__
    (code, msg) = self.connect(host, port)
                  ^^^^^^^^^^^^^^^^^^^^^^^^
  File "C:\Users\sesel\AppData\Local\Programs\Python\Python311\Lib\smtplib.py", line 343, in connect
    (code, msg) = self.getreply()
                  ^^^^^^^^^^^^^^^
  File "C:\Users\sesel\AppData\Local\Programs\Python\Python311\Lib\smtplib.py", line 405, in getreply
    raise SMTPServerDisconnected("Connection unexpectedly closed")
smtplib.SMTPServerDisconnected: Connection unexpectedly closed
[2023-06-20 04:57:39,595] INFO in _internal: 127.0.0.1 - - [20/Jun/2023 04:57:39] "[35m[1mPOST /register HTTP/1.1[0m" 500 -
[2023-06-20 04:57:39,634] INFO in _internal: 127.0.0.1 - - [20/Jun/2023 04:57:39] "[36mGET /static/images/500.jpg HTTP/1.1[0m" 304 -
[2023-06-20 04:58:07,961] INFO in _internal: 127.0.0.1 - - [20/Jun/2023 04:58:07] "[32mPOST /register HTTP/1.1[0m" 302 -
[2023-06-20 04:58:07,970] INFO in _internal: 127.0.0.1 - - [20/Jun/2023 04:58:07] "GET /register HTTP/1.1" 200 -
[2023-06-20 04:58:43,440] ERROR in app: Exception on /register [POST]
Traceback (most recent call last):
  File "C:\Users\sesel\OneDrive\Desktop\Projects\secure-web-app\venv\Lib\site-packages\flask\app.py", line 2190, in wsgi_app
    response = self.full_dispatch_request()
               ^^^^^^^^^^^^^^^^^^^^^^^^^^^^
  File "C:\Users\sesel\OneDrive\Desktop\Projects\secure-web-app\venv\Lib\site-packages\flask\app.py", line 1486, in full_dispatch_request
    rv = self.handle_user_exception(e)
         ^^^^^^^^^^^^^^^^^^^^^^^^^^^^^
  File "C:\Users\sesel\OneDrive\Desktop\Projects\secure-web-app\venv\Lib\site-packages\flask\app.py", line 1484, in full_dispatch_request
    rv = self.dispatch_request()
         ^^^^^^^^^^^^^^^^^^^^^^^
  File "C:\Users\sesel\OneDrive\Desktop\Projects\secure-web-app\venv\Lib\site-packages\flask\app.py", line 1469, in dispatch_request
    return self.ensure_sync(self.view_functions[rule.endpoint])(**view_args)
           ^^^^^^^^^^^^^^^^^^^^^^^^^^^^^^^^^^^^^^^^^^^^^^^^^^^^^^^^^^^^^^^^^
  File "C:\Users\sesel\OneDrive\Desktop\Projects\secure-web-app\app\routes.py", line 126, in register
    send_verification_email(email, verification_link)
  File "C:\Users\sesel\OneDrive\Desktop\Projects\secure-web-app\app\routes.py", line 77, in send_verification_email
    mail.send(msg)
  File "C:\Users\sesel\OneDrive\Desktop\Projects\secure-web-app\venv\Lib\site-packages\flask_mail.py", line 491, in send
    with self.connect() as connection:
  File "C:\Users\sesel\OneDrive\Desktop\Projects\secure-web-app\venv\Lib\site-packages\flask_mail.py", line 144, in __enter__
    self.host = self.configure_host()
                ^^^^^^^^^^^^^^^^^^^^^
  File "C:\Users\sesel\OneDrive\Desktop\Projects\secure-web-app\venv\Lib\site-packages\flask_mail.py", line 158, in configure_host
    host = smtplib.SMTP(self.mail.server, self.mail.port)
           ^^^^^^^^^^^^^^^^^^^^^^^^^^^^^^^^^^^^^^^^^^^^^^
  File "C:\Users\sesel\AppData\Local\Programs\Python\Python311\Lib\smtplib.py", line 255, in __init__
    (code, msg) = self.connect(host, port)
                  ^^^^^^^^^^^^^^^^^^^^^^^^
  File "C:\Users\sesel\AppData\Local\Programs\Python\Python311\Lib\smtplib.py", line 343, in connect
    (code, msg) = self.getreply()
                  ^^^^^^^^^^^^^^^
  File "C:\Users\sesel\AppData\Local\Programs\Python\Python311\Lib\smtplib.py", line 405, in getreply
    raise SMTPServerDisconnected("Connection unexpectedly closed")
smtplib.SMTPServerDisconnected: Connection unexpectedly closed
[2023-06-20 04:58:43,443] INFO in _internal: 127.0.0.1 - - [20/Jun/2023 04:58:43] "[35m[1mPOST /register HTTP/1.1[0m" 500 -
[2023-06-20 04:58:43,498] INFO in _internal: 127.0.0.1 - - [20/Jun/2023 04:58:43] "[36mGET /static/images/500.jpg HTTP/1.1[0m" 304 -
[2023-06-20 05:02:50,046] INFO in _internal: 127.0.0.1 - - [20/Jun/2023 05:02:50] "[32mPOST /register HTTP/1.1[0m" 302 -
[2023-06-20 05:02:50,059] INFO in _internal: 127.0.0.1 - - [20/Jun/2023 05:02:50] "GET /register HTTP/1.1" 200 -
[2023-06-20 05:03:36,880] ERROR in app: Exception on /register [POST]
Traceback (most recent call last):
  File "C:\Users\sesel\OneDrive\Desktop\Projects\secure-web-app\venv\Lib\site-packages\flask\app.py", line 2190, in wsgi_app
    response = self.full_dispatch_request()
               ^^^^^^^^^^^^^^^^^^^^^^^^^^^^
  File "C:\Users\sesel\OneDrive\Desktop\Projects\secure-web-app\venv\Lib\site-packages\flask\app.py", line 1486, in full_dispatch_request
    rv = self.handle_user_exception(e)
         ^^^^^^^^^^^^^^^^^^^^^^^^^^^^^
  File "C:\Users\sesel\OneDrive\Desktop\Projects\secure-web-app\venv\Lib\site-packages\flask\app.py", line 1484, in full_dispatch_request
    rv = self.dispatch_request()
         ^^^^^^^^^^^^^^^^^^^^^^^
  File "C:\Users\sesel\OneDrive\Desktop\Projects\secure-web-app\venv\Lib\site-packages\flask\app.py", line 1469, in dispatch_request
    return self.ensure_sync(self.view_functions[rule.endpoint])(**view_args)
           ^^^^^^^^^^^^^^^^^^^^^^^^^^^^^^^^^^^^^^^^^^^^^^^^^^^^^^^^^^^^^^^^^
  File "C:\Users\sesel\OneDrive\Desktop\Projects\secure-web-app\app\routes.py", line 126, in register
    send_verification_email(email, verification_link)
  File "C:\Users\sesel\OneDrive\Desktop\Projects\secure-web-app\app\routes.py", line 77, in send_verification_email
    mail.send(msg)
  File "C:\Users\sesel\OneDrive\Desktop\Projects\secure-web-app\venv\Lib\site-packages\flask_mail.py", line 491, in send
    with self.connect() as connection:
  File "C:\Users\sesel\OneDrive\Desktop\Projects\secure-web-app\venv\Lib\site-packages\flask_mail.py", line 144, in __enter__
    self.host = self.configure_host()
                ^^^^^^^^^^^^^^^^^^^^^
  File "C:\Users\sesel\OneDrive\Desktop\Projects\secure-web-app\venv\Lib\site-packages\flask_mail.py", line 158, in configure_host
    host = smtplib.SMTP(self.mail.server, self.mail.port)
           ^^^^^^^^^^^^^^^^^^^^^^^^^^^^^^^^^^^^^^^^^^^^^^
  File "C:\Users\sesel\AppData\Local\Programs\Python\Python311\Lib\smtplib.py", line 255, in __init__
    (code, msg) = self.connect(host, port)
                  ^^^^^^^^^^^^^^^^^^^^^^^^
  File "C:\Users\sesel\AppData\Local\Programs\Python\Python311\Lib\smtplib.py", line 343, in connect
    (code, msg) = self.getreply()
                  ^^^^^^^^^^^^^^^
  File "C:\Users\sesel\AppData\Local\Programs\Python\Python311\Lib\smtplib.py", line 405, in getreply
    raise SMTPServerDisconnected("Connection unexpectedly closed")
smtplib.SMTPServerDisconnected: Connection unexpectedly closed
[2023-06-20 05:03:36,883] INFO in _internal: 127.0.0.1 - - [20/Jun/2023 05:03:36] "[35m[1mPOST /register HTTP/1.1[0m" 500 -
[2023-06-20 05:03:36,927] INFO in _internal: 127.0.0.1 - - [20/Jun/2023 05:03:36] "[36mGET /static/images/500.jpg HTTP/1.1[0m" 304 -
[2023-06-20 05:05:08,027] INFO in _internal: 127.0.0.1 - - [20/Jun/2023 05:05:08] "GET /register HTTP/1.1" 200 -
[2023-06-20 05:05:20,466] INFO in _internal: 127.0.0.1 - - [20/Jun/2023 05:05:20] "[32mPOST /register HTTP/1.1[0m" 302 -
[2023-06-20 05:05:20,482] INFO in _internal: 127.0.0.1 - - [20/Jun/2023 05:05:20] "GET /register HTTP/1.1" 200 -
[2023-06-20 05:05:54,170] ERROR in app: Exception on /register [POST]
Traceback (most recent call last):
  File "C:\Users\sesel\OneDrive\Desktop\Projects\secure-web-app\venv\Lib\site-packages\flask\app.py", line 2190, in wsgi_app
    response = self.full_dispatch_request()
               ^^^^^^^^^^^^^^^^^^^^^^^^^^^^
  File "C:\Users\sesel\OneDrive\Desktop\Projects\secure-web-app\venv\Lib\site-packages\flask\app.py", line 1486, in full_dispatch_request
    rv = self.handle_user_exception(e)
         ^^^^^^^^^^^^^^^^^^^^^^^^^^^^^
  File "C:\Users\sesel\OneDrive\Desktop\Projects\secure-web-app\venv\Lib\site-packages\flask\app.py", line 1484, in full_dispatch_request
    rv = self.dispatch_request()
         ^^^^^^^^^^^^^^^^^^^^^^^
  File "C:\Users\sesel\OneDrive\Desktop\Projects\secure-web-app\venv\Lib\site-packages\flask\app.py", line 1469, in dispatch_request
    return self.ensure_sync(self.view_functions[rule.endpoint])(**view_args)
           ^^^^^^^^^^^^^^^^^^^^^^^^^^^^^^^^^^^^^^^^^^^^^^^^^^^^^^^^^^^^^^^^^
  File "C:\Users\sesel\OneDrive\Desktop\Projects\secure-web-app\app\routes.py", line 126, in register
    send_verification_email(email, verification_link)
  File "C:\Users\sesel\OneDrive\Desktop\Projects\secure-web-app\app\routes.py", line 77, in send_verification_email
    mail.send(msg)
  File "C:\Users\sesel\OneDrive\Desktop\Projects\secure-web-app\venv\Lib\site-packages\flask_mail.py", line 491, in send
    with self.connect() as connection:
  File "C:\Users\sesel\OneDrive\Desktop\Projects\secure-web-app\venv\Lib\site-packages\flask_mail.py", line 144, in __enter__
    self.host = self.configure_host()
                ^^^^^^^^^^^^^^^^^^^^^
  File "C:\Users\sesel\OneDrive\Desktop\Projects\secure-web-app\venv\Lib\site-packages\flask_mail.py", line 158, in configure_host
    host = smtplib.SMTP(self.mail.server, self.mail.port)
           ^^^^^^^^^^^^^^^^^^^^^^^^^^^^^^^^^^^^^^^^^^^^^^
  File "C:\Users\sesel\AppData\Local\Programs\Python\Python311\Lib\smtplib.py", line 255, in __init__
    (code, msg) = self.connect(host, port)
                  ^^^^^^^^^^^^^^^^^^^^^^^^
  File "C:\Users\sesel\AppData\Local\Programs\Python\Python311\Lib\smtplib.py", line 343, in connect
    (code, msg) = self.getreply()
                  ^^^^^^^^^^^^^^^
  File "C:\Users\sesel\AppData\Local\Programs\Python\Python311\Lib\smtplib.py", line 405, in getreply
    raise SMTPServerDisconnected("Connection unexpectedly closed")
smtplib.SMTPServerDisconnected: Connection unexpectedly closed
[2023-06-20 05:05:54,173] INFO in _internal: 127.0.0.1 - - [20/Jun/2023 05:05:54] "[35m[1mPOST /register HTTP/1.1[0m" 500 -
[2023-06-20 05:05:54,248] INFO in _internal: 127.0.0.1 - - [20/Jun/2023 05:05:54] "[36mGET /static/images/500.jpg HTTP/1.1[0m" 304 -
[2023-06-20 05:05:56,287] INFO in _internal: 127.0.0.1 - - [20/Jun/2023 05:05:56] "GET /register HTTP/1.1" 200 -
[2023-06-20 05:07:46,372] INFO in _internal: [31m[1mWARNING: This is a development server. Do not use it in a production deployment. Use a production WSGI server instead.[0m
 * Running on http://127.0.0.1:5000
[2023-06-20 05:07:46,373] INFO in _internal: [33mPress CTRL+C to quit[0m
[2023-06-20 05:08:12,043] INFO in _internal: 127.0.0.1 - - [20/Jun/2023 05:08:12] "GET /register HTTP/1.1" 200 -
[2023-06-20 05:08:47,379] ERROR in app: Exception on /register [POST]
Traceback (most recent call last):
  File "C:\Users\sesel\OneDrive\Desktop\Projects\secure-web-app\venv\Lib\site-packages\flask\app.py", line 2190, in wsgi_app
    response = self.full_dispatch_request()
               ^^^^^^^^^^^^^^^^^^^^^^^^^^^^
  File "C:\Users\sesel\OneDrive\Desktop\Projects\secure-web-app\venv\Lib\site-packages\flask\app.py", line 1486, in full_dispatch_request
    rv = self.handle_user_exception(e)
         ^^^^^^^^^^^^^^^^^^^^^^^^^^^^^
  File "C:\Users\sesel\OneDrive\Desktop\Projects\secure-web-app\venv\Lib\site-packages\flask\app.py", line 1484, in full_dispatch_request
    rv = self.dispatch_request()
         ^^^^^^^^^^^^^^^^^^^^^^^
  File "C:\Users\sesel\OneDrive\Desktop\Projects\secure-web-app\venv\Lib\site-packages\flask\app.py", line 1469, in dispatch_request
    return self.ensure_sync(self.view_functions[rule.endpoint])(**view_args)
           ^^^^^^^^^^^^^^^^^^^^^^^^^^^^^^^^^^^^^^^^^^^^^^^^^^^^^^^^^^^^^^^^^
  File "C:\Users\sesel\OneDrive\Desktop\Projects\secure-web-app\app\routes.py", line 126, in register
    send_verification_email(email, verification_link)
  File "C:\Users\sesel\OneDrive\Desktop\Projects\secure-web-app\app\routes.py", line 77, in send_verification_email
    mail.send(msg)
  File "C:\Users\sesel\OneDrive\Desktop\Projects\secure-web-app\venv\Lib\site-packages\flask_mail.py", line 491, in send
    with self.connect() as connection:
  File "C:\Users\sesel\OneDrive\Desktop\Projects\secure-web-app\venv\Lib\site-packages\flask_mail.py", line 144, in __enter__
    self.host = self.configure_host()
                ^^^^^^^^^^^^^^^^^^^^^
  File "C:\Users\sesel\OneDrive\Desktop\Projects\secure-web-app\venv\Lib\site-packages\flask_mail.py", line 158, in configure_host
    host = smtplib.SMTP(self.mail.server, self.mail.port)
           ^^^^^^^^^^^^^^^^^^^^^^^^^^^^^^^^^^^^^^^^^^^^^^
  File "C:\Users\sesel\AppData\Local\Programs\Python\Python311\Lib\smtplib.py", line 255, in __init__
    (code, msg) = self.connect(host, port)
                  ^^^^^^^^^^^^^^^^^^^^^^^^
  File "C:\Users\sesel\AppData\Local\Programs\Python\Python311\Lib\smtplib.py", line 341, in connect
    self.sock = self._get_socket(host, port, self.timeout)
                ^^^^^^^^^^^^^^^^^^^^^^^^^^^^^^^^^^^^^^^^^^
  File "C:\Users\sesel\AppData\Local\Programs\Python\Python311\Lib\smtplib.py", line 312, in _get_socket
    return socket.create_connection((host, port), timeout,
           ^^^^^^^^^^^^^^^^^^^^^^^^^^^^^^^^^^^^^^^^^^^^^^^
  File "C:\Users\sesel\AppData\Local\Programs\Python\Python311\Lib\socket.py", line 851, in create_connection
    raise exceptions[0]
  File "C:\Users\sesel\AppData\Local\Programs\Python\Python311\Lib\socket.py", line 836, in create_connection
    sock.connect(sa)
ConnectionRefusedError: [WinError 10061] No connection could be made because the target machine actively refused it
[2023-06-20 05:08:47,397] INFO in _internal: 127.0.0.1 - - [20/Jun/2023 05:08:47] "[35m[1mPOST /register HTTP/1.1[0m" 500 -
[2023-06-20 05:08:47,574] INFO in _internal: 127.0.0.1 - - [20/Jun/2023 05:08:47] "[36mGET /static/images/500.jpg HTTP/1.1[0m" 304 -
[2023-06-20 05:11:06,959] ERROR in app: Exception on /register [POST]
Traceback (most recent call last):
  File "C:\Users\sesel\OneDrive\Desktop\Projects\secure-web-app\venv\Lib\site-packages\flask\app.py", line 2190, in wsgi_app
    response = self.full_dispatch_request()
               ^^^^^^^^^^^^^^^^^^^^^^^^^^^^
  File "C:\Users\sesel\OneDrive\Desktop\Projects\secure-web-app\venv\Lib\site-packages\flask\app.py", line 1486, in full_dispatch_request
    rv = self.handle_user_exception(e)
         ^^^^^^^^^^^^^^^^^^^^^^^^^^^^^
  File "C:\Users\sesel\OneDrive\Desktop\Projects\secure-web-app\venv\Lib\site-packages\flask\app.py", line 1484, in full_dispatch_request
    rv = self.dispatch_request()
         ^^^^^^^^^^^^^^^^^^^^^^^
  File "C:\Users\sesel\OneDrive\Desktop\Projects\secure-web-app\venv\Lib\site-packages\flask\app.py", line 1469, in dispatch_request
    return self.ensure_sync(self.view_functions[rule.endpoint])(**view_args)
           ^^^^^^^^^^^^^^^^^^^^^^^^^^^^^^^^^^^^^^^^^^^^^^^^^^^^^^^^^^^^^^^^^
  File "C:\Users\sesel\OneDrive\Desktop\Projects\secure-web-app\app\routes.py", line 126, in register
    send_verification_email(email, verification_link)
  File "C:\Users\sesel\OneDrive\Desktop\Projects\secure-web-app\app\routes.py", line 77, in send_verification_email
    mail.send(msg)
  File "C:\Users\sesel\OneDrive\Desktop\Projects\secure-web-app\venv\Lib\site-packages\flask_mail.py", line 491, in send
    with self.connect() as connection:
  File "C:\Users\sesel\OneDrive\Desktop\Projects\secure-web-app\venv\Lib\site-packages\flask_mail.py", line 144, in __enter__
    self.host = self.configure_host()
                ^^^^^^^^^^^^^^^^^^^^^
  File "C:\Users\sesel\OneDrive\Desktop\Projects\secure-web-app\venv\Lib\site-packages\flask_mail.py", line 158, in configure_host
    host = smtplib.SMTP(self.mail.server, self.mail.port)
           ^^^^^^^^^^^^^^^^^^^^^^^^^^^^^^^^^^^^^^^^^^^^^^
  File "C:\Users\sesel\AppData\Local\Programs\Python\Python311\Lib\smtplib.py", line 255, in __init__
    (code, msg) = self.connect(host, port)
                  ^^^^^^^^^^^^^^^^^^^^^^^^
  File "C:\Users\sesel\AppData\Local\Programs\Python\Python311\Lib\smtplib.py", line 341, in connect
    self.sock = self._get_socket(host, port, self.timeout)
                ^^^^^^^^^^^^^^^^^^^^^^^^^^^^^^^^^^^^^^^^^^
  File "C:\Users\sesel\AppData\Local\Programs\Python\Python311\Lib\smtplib.py", line 312, in _get_socket
    return socket.create_connection((host, port), timeout,
           ^^^^^^^^^^^^^^^^^^^^^^^^^^^^^^^^^^^^^^^^^^^^^^^
  File "C:\Users\sesel\AppData\Local\Programs\Python\Python311\Lib\socket.py", line 851, in create_connection
    raise exceptions[0]
  File "C:\Users\sesel\AppData\Local\Programs\Python\Python311\Lib\socket.py", line 836, in create_connection
    sock.connect(sa)
ConnectionRefusedError: [WinError 10061] No connection could be made because the target machine actively refused it
[2023-06-20 05:11:06,964] INFO in _internal: 127.0.0.1 - - [20/Jun/2023 05:11:06] "[35m[1mPOST /register HTTP/1.1[0m" 500 -
[2023-06-20 05:11:07,028] INFO in _internal: 127.0.0.1 - - [20/Jun/2023 05:11:07] "[36mGET /static/images/500.jpg HTTP/1.1[0m" 304 -
